Failure # 1 (occurred at 2021-11-13_04-21-15)
Traceback (most recent call last):
  File "/home/werikcyano/.local/lib/python3.8/site-packages/ray/tune/trial_runner.py", line 718, in _process_trial
    results = self.trial_executor.fetch_result(trial)
  File "/home/werikcyano/.local/lib/python3.8/site-packages/ray/tune/ray_trial_executor.py", line 688, in fetch_result
    result = ray.get(trial_future[0], timeout=DEFAULT_GET_TIMEOUT)
  File "/home/werikcyano/.local/lib/python3.8/site-packages/ray/_private/client_mode_hook.py", line 62, in wrapper
    return func(*args, **kwargs)
  File "/home/werikcyano/.local/lib/python3.8/site-packages/ray/worker.py", line 1494, in get
    raise value.as_instanceof_cause()
ray.exceptions.RayTaskError(ValueError): [36mray::SAC.train_buffered()[39m (pid=40147, ip=192.168.1.8)
  File "python/ray/_raylet.pyx", line 501, in ray._raylet.execute_task
  File "python/ray/_raylet.pyx", line 451, in ray._raylet.execute_task.function_executor
  File "/home/werikcyano/.local/lib/python3.8/site-packages/ray/_private/function_manager.py", line 563, in actor_method_executor
    return method(__ray_actor, *args, **kwargs)
  File "/home/werikcyano/.local/lib/python3.8/site-packages/ray/tune/trainable.py", line 173, in train_buffered
    result = self.train()
  File "/home/werikcyano/.local/lib/python3.8/site-packages/ray/rllib/agents/trainer.py", line 608, in train
    raise e
  File "/home/werikcyano/.local/lib/python3.8/site-packages/ray/rllib/agents/trainer.py", line 594, in train
    result = Trainable.train(self)
  File "/home/werikcyano/.local/lib/python3.8/site-packages/ray/tune/trainable.py", line 232, in train
    result = self.step()
  File "/home/werikcyano/.local/lib/python3.8/site-packages/ray/rllib/agents/trainer_template.py", line 173, in step
    res = next(self.train_exec_impl)
  File "/home/werikcyano/.local/lib/python3.8/site-packages/ray/util/iter.py", line 756, in __next__
    return next(self.built_iterator)
  File "/home/werikcyano/.local/lib/python3.8/site-packages/ray/util/iter.py", line 783, in apply_foreach
    for item in it:
  File "/home/werikcyano/.local/lib/python3.8/site-packages/ray/util/iter.py", line 843, in apply_filter
    for item in it:
  File "/home/werikcyano/.local/lib/python3.8/site-packages/ray/util/iter.py", line 843, in apply_filter
    for item in it:
  File "/home/werikcyano/.local/lib/python3.8/site-packages/ray/util/iter.py", line 783, in apply_foreach
    for item in it:
  File "/home/werikcyano/.local/lib/python3.8/site-packages/ray/util/iter.py", line 843, in apply_filter
    for item in it:
  File "/home/werikcyano/.local/lib/python3.8/site-packages/ray/util/iter.py", line 1075, in build_union
    item = next(it)
  File "/home/werikcyano/.local/lib/python3.8/site-packages/ray/util/iter.py", line 756, in __next__
    return next(self.built_iterator)
  File "/home/werikcyano/.local/lib/python3.8/site-packages/ray/util/iter.py", line 783, in apply_foreach
    for item in it:
  File "/home/werikcyano/.local/lib/python3.8/site-packages/ray/util/iter.py", line 791, in apply_foreach
    result = fn(item)
  File "/home/werikcyano/.local/lib/python3.8/site-packages/ray/rllib/execution/replay_ops.py", line 49, in __call__
    self.local_actor.add_batch(batch)
  File "/home/werikcyano/.local/lib/python3.8/site-packages/ray/rllib/execution/replay_buffer.py", line 408, in add_batch
    self.replay_buffers[policy_id].add(
  File "/home/werikcyano/.local/lib/python3.8/site-packages/ray/rllib/execution/replay_buffer.py", line 164, in add
    super(PrioritizedReplayBuffer, self).add(item, weight)
  File "/home/werikcyano/.local/lib/python3.8/site-packages/ray/rllib/execution/replay_buffer.py", line 74, in add
    warn_replay_buffer_size(
  File "/home/werikcyano/.local/lib/python3.8/site-packages/ray/rllib/execution/replay_buffer.py", line 42, in warn_replay_buffer_size
    raise ValueError(msg)
ValueError: Estimated max memory usage for replay buffer is 56.497 GB (1000000.0 batches of size 1, 56497 bytes each), available system memory is 16.677036032 GB

